Workbook

Sheet How to Use
A1: Project Pricing Workbook
A2: One tab per build platform. Same columns on every tab, so you can compare like for like.
A4: TABS
A5: Categories | B5: Master category list. Every task points to one of these by category_id.
A6: Rates | B6: Your hourly rates. Fill in the yellow cells. Every tab reads from here.
A7: WordPress / Squarespace / Shopify / WIX / PHP-HTML-CSS / React-NextJS | B7: The task libraries. Filter by Category, Responsible, or Level to build a quote.
A8: Summary | B8: Total hours and cost per platform, so you can compare platforms at a glance.
A10: COLUMNS
A11: category_id / Category | B11: Which category the task belongs to. Category name fills in automatically.
A12: Base Hours | B12: Your original hours. I did not change any of them.
A13: Responsible | B13: Who does the work: IT, Creative, Project Manager, QA Tester, or Project Coordinator.
A14: Level | B14: Level 1 = standard config and build work. Level 2 = senior, custom-coded, or higher-risk work.
A15: Rate | B15: Pulled automatically from the Rates tab using Responsible + Level.
A16: Estimated Cost | B16: Base Hours x Rate.
A17: Hours – Things to Consider | B17: What can push the hours up or down. A note only; it changes no calculation.
A19: HOW TO QUOTE A JOB
A20: Step 1 | B20: Open the tab for the platform you are building on.
A21: Step 2 | B21: Filter or highlight only the tasks that job actually needs.
A22: Step 3 | B22: Read the 'Things to Consider' notes before you commit to the hours.
A23: Step 4 | B23: Add up the Estimated Cost of the tasks you selected. The tab TOTAL is the whole library, not a quote.
A25: STILL TO ADD
A26: Difficulty sub-category | B26: Easy / Medium / Hard inside each category, so harder tasks bill more than easy ones.
A27: Discovery, PM, Docs & Training | B27: Categories 10, 11, 21 exist but have no tasks yet on any tab.
A28: Local SEO / SEO off-page / Maintenance | B28: Categories 16, 17, 23 exist but have no tasks yet on any tab.

Sheet Categories
A1: Categories
A2: Add a new category here and it becomes available to every platform tab.
A4: category_id | B4: Category | C4: Description
A5: 1 | B5: Accessibility | C5: Making the site usable for people with disabilities (WCAG/ADA compliance).
A6: 2 | B6: Backend | C6: Server-side logic, APIs, and application functionality.
A7: 3 | B7: CMS & Content Prep | C7: Setting up the CMS and preparing content so the client can manage the site.
A8: 4 | B8: Conversion Tracking | C8: Measuring and reporting the actions visitors take on the site.
A9: 5 | B9: Custom Tools | C9: Calculators, configurators, and other custom-built features.
A10: 6 | B10: Data Migration | C10: Moving content, users, and data from an old system to the new one.
A11: 7 | B11: Database | C11: Designing, building, and optimizing the database that stores project data.
A12: 8 | B12: Deployment | C12: Publishing the site or software to the live server.
A13: 9 | B13: Design | C13: Visual design, layouts, and user experience.
A14: 10 | B14: Discovery & Planning | C14: Gathering requirements, scoping the project, and planning the build.
A15: 11 | B15: Documentation & Training | C15: User guides and training so the client can run the site themselves.
A16: 12 | B16: E-Commerce | C16: Online store features, product catalog, cart, and checkout.
... A27: 25 | B27: QA & Testing | C27: Testing the site or software to find and fix bugs before launch.

Sheet Rates
A1: Hourly Rates
A2: EDIT THE YELLOW CELLS. These feed the Rate and Estimated Cost columns on every platform tab.
A3: Level 2 = senior / higher skill / higher risk. It should always be priced above Level 1.
A5: Responsible | B5: Level | C5: Lookup Key | D5: Hourly Rate
A6: IT | B6: Level 1 | C6: =A6&"|"&B6 -> IT|Level 1 | D6: 100
A7: IT | B7: Level 2 | C7: =A7&"|"&B7 -> IT|Level 2 | D7: 120
A8: Creative | B8: Level 1 | C8: =A8&"|"&B8 -> Creative|Level 1 | D8: 100
A9: Creative | B9: Level 2 | C9: =A9&"|"&B9 -> Creative|Level 2 | D9: 130
A10: Project Manager | B10: Level 1 | C10: =A10&"|"&B10 -> Project Manager|Level 1 | D10: 80
A11: Project Manager | B11: Level 2 | C11: =A11&"|"&B11 -> Project Manager|Level 2 | D11: 100
A12: QA Tester | B12: Level 1 | C12: =A12&"|"&B12 -> QA Tester|Level 1 | D12: 80
A13: QA Tester | B13: Level 2 | C13: =A13&"|"&B13 -> QA Tester|Level 2 | D13: 120
A14: Project Coordinator | B14: Level 1 | C14: =A14&"|"&B14 -> Project Coordinator|Level 1 | D14: 0
A15: Project Coordinator | B15: Level 2 | C15: =A15&"|"&B15 -> Project Coordinator|Level 2 | D15: 0
A17: These are placeholder examples only. Your edited rates were not in the file you sent, so replace these with your own numbers.

Sheet WordPress
A1: Task Pricing – WordPress
A2: Base Hours unchanged from your original sheet.
A4: id | B4: Dependencies | C4: Module | D4: Name | E4: category_id | F4: Category | G4: Description | H4: Responsible | I4: Level | J4: Rate | K4: Base Hours | L4: Estimated Cost | M4: Hours – Things to Consider
A5: 1 | C5: Homepage – Standard | D5: Hero Section | E5: 14 | F5: =IFERROR(INDEX(Categories!$B$5:$B$27,MATCH(E5,Categories!$A$5:$A$27,0)),"") -> Frontend | G5: Hero section and headline | H5: IT | I5: Level 1 | J5: =IFERROR(INDEX(Rates!$D$6:$D$15,MATCH(H5&"|"&I5,Rates!$C$6:$C$15,0)),0) -> 100 | K5: 1.5 | L5: =K5*J5 -> 150 | M5: Assumes design is already approved. Add hours if animation or video background is required.
A6: 2 | C6: Homepage – Standard | D6: Services or Product Grid | E6: 14 | F6: =IFERROR(INDEX(Categories!$B$5:$B$27,MATCH(E6,Categories!$A$5:$A$27,0)),"") -> Frontend | G6: Grid layout for displaying services, products, programs, or offerings (including nonprofit initiatives or services). | H6: IT | I6: Level 1 | J6: =IFERROR(INDEX(Rates!$D$6:$D$15,MATCH(H6&"|"&I6,Rates!$C$6:$C$15,0)),0) -> 100 | K6: 2.5 | L6: =K6*J6 -> 250 | M6: Assumes a fixed number of items. Dynamic/CPT-driven grids cost more.
A7: 3 | C7: Homepage – Standard | D7: Testimonials Slider-Dynamic | E7: 15 | F7: =IFERROR(INDEX(Categories!$B$5:$B$27,MATCH(E7,Categories!$A$5:$A$27,0)),"") -> Integration | G7: Dynamic testimonials integration via external API (e.g., review platforms), not embed-based | H7: IT | I7: Level 2 | J7: =IFERROR(INDEX(Rates!$D$6:$D$15,MATCH(H7&"|"&I7,Rates!$C$6:$C$15,0)),0) -> 120 | K7: 8 | L7: =K7*J7 -> 960 | M7: Depends on the review platform's API. Add hours if API keys, rate limits, or caching are involved.
A8: 4 | C8: Homepage – Standard | D8: Testimonials Slider- embed | E8: 15 | F8: =IFERROR(INDEX(Categories!$B$5:$B$27,MATCH(E8,Categories!$A$5:$A$27,0)),"") -> Integration | G8: Embedded testimonials using iframe or widget from external platforms. | H8: IT | I8: Level 1 | J8: =IFERROR(INDEX(Rates!$D$6:$D$15,MATCH(H8&"|"&I8,Rates!$C$6:$C$15,0)),0) -> 100 | K8: 3 | L8: =K8*J8 -> 300 | M8: Styling a third-party widget can take longer than expected if the platform limits CSS.
A9: 5 | C9: Homepage – Standard | D9: Team Preview | E9: 14 | F9: =IFERROR(INDEX(Categories!$B$5:$B$27,MATCH(E9,Categories!$A$5:$A$27,0)),"") -> Frontend | G9: Section highlighting team members, staff, or key representatives | H9: IT | I9: Level 1 | J9: =IFERROR(INDEX(Rates!$D$6:$D$15,MATCH(H9&"|"&I9,Rates!$C$6:$C$15,0)),0) -> 100 | K9: 1.5 | L9: =K9*J9 -> 150 | M9: Per-person bios and photo cropping are usually content work, not build work.
A10: 6 | C10: Homepage – Standard | D10: Footer Layout | E10: 14 | F10: =IFERROR(INDEX(Categories!$B$5:$B$27,MATCH(E10,Categories!$A$5:$A$27,0)),"") -> Frontend | G10: Structured footer with navigation and contact info | H10: IT | I10: Level 1 | J10: =IFERROR(INDEX(Rates!$D$6:$D$15,MATCH(H10&"|"&I10,Rates!$C$6:$C$15,0)),0) -> 100 | K10: 1.5 | L10: =K10*J10 -> 150 | M10: Mega-footers with multiple menus and a newsletter form run higher.
A11: 7 | C11: Homepage – Conversion | D11: Strong Hero Offer | E11: 14 | F11: =IFERROR(INDEX(Categories!$B$5:$B$27,MATCH(E11,Categories!$A$5:$A$27,0)),"") -> Frontend | G11: Strong hero offer with CTA | H11: IT | I11: Level 1 | J11: =IFERROR(INDEX(Rates!$D$6:$D$15,MATCH(H11&"|"&I11,Rates!$C$6:$C$15,0)),0) -> 100 | K11: 4 | L11: =K11*J11 -> 400 | M11: Add hours if A/B variants of the hero are required.
A12: 8 | C12: Homepage – Conversion | D12: Benefits/Features | E12: 14 | F12: =IFERROR(INDEX(Categories!$B$5:$B$27,MATCH(E12,Categories!$A$5:$A$27,0)),"") -> Frontend | G12: Highlight product/service benefits | H12: IT | I12: Level 1 | J12: =IFERROR(INDEX(Rates!$D$6:$D$15,MATCH(H12&"|"&I12,Rates!$C$6:$C$15,0)),0) -> 100 | K12: 3 | L12: =K12*J12 -> 300 | M12: Icon sourcing or custom icons may need Creative hours on top.
A13: 9 | C13: Homepage – Conversion | D13: Social Proof / Trust Badges | E13: 14 | F13: =IFERROR(INDEX(Categories!$B$5:$B$27,MATCH(E13,Categories!$A$5:$A$27,0)),"") -> Frontend | G13: Section showcasing logos, trust badges, or affiliations to build credibility, reinforce trust, and support conversion. | H13: IT | I13: Level 1 | J13: =IFERROR(INDEX(Rates!$D$6:$D$15,MATCH(H13&"|"&I13,Rates!$C$6:$C$15,0)),0) -> 100 | K13: 2 | L13: =K13*J13 -> 200 | M13: Assumes client supplies logos in usable formats. Logo cleanup is Creative time.
A14: 10 | C14: Homepage – Conversion | D14: FAQ Section | E14: 14 | F14: =IFERROR(INDEX(Categories!$B$5:$B$27,MATCH(E14,Categories!$A$5:$A$27,0)),"") -> Frontend | G14: Frequently asked questions block | H14: IT | I14: Level 1 | J14: =IFERROR(INDEX(Rates!$D$6:$D$15,MATCH(H14&"|"&I14,Rates!$C$6:$C$15,0)),0) -> 100 | K14: 2 | L14: =K14*J14 -> 200 | M14: Add a little time if FAQ schema markup is also required (see Schema Markup).
A15: 11 | C15: Homepage – Standard | D15: Pricing Tables | E15: 14 | F15: =IFERROR(INDEX(Categories!$B$5:$B$27,MATCH(E15,Categories!$A$5:$A$27,0)),"") -> Frontend | G15: Structured plans with features and comparison layout | H15: IT | I15: Level 1 | J15: =IFERROR(INDEX(Rates!$D$6:$D$15,MATCH(H15&"|"&I15,Rates!$C$6:$C$15,0)),0) -> 100 | K15: 4 | L15: =K15*J15 -> 400 | M15: Monthly/annual toggles or more than 3 plans push this higher.
A16: 12 | C16: Homepage – Standard | D16: Galleries | E16: 14 | F16: =IFERROR(INDEX(Categories!$B$5:$B$27,MATCH(E16,Categories!$A$5:$A$27,0)),"") -> Frontend | G16: Image gallery layout for showcasing media (grid, slider, or lightbox) | H16: IT | I16: Level 1 | J16: =IFERROR(INDEX(Rates!$D$6:$D$15,MATCH(H16&"|"&I16,Rates!$C$6:$C$15,0)),0) -> 100 | K16: 2 | L16: =K16*J16 -> 200 | M16: Assumes one gallery. Price per additional gallery, and add image prep time.
... A18: 14 | C18: Homepage - Standard | D18: Payment / Contribution Module | E18: 15 | F18: =IFERROR(INDEX(Categories!$B$5:$B$27,MATCH(E18,Categories!$A$5:$A$27,0)),"") -> Integration | G18: Payment or contribution functionality using plugin-based integration (e.g., Stripe/PayPal), no custom gateway. | H18: IT | I18: Level 2 | J18: =IFERROR(INDEX(Rates!$D$6:$D$15,MATCH(H18&"|"&I18,Rates!$C$6:$C$15,0)),0) -> 120 | K18: 5 | L18: =K18*J18 -> 600 | M18: Excludes merchant account setup and recurring donations. Test-mode and live-mode testing both take time.
A19: 15 | C19: Homepage - Standard | D19: Use Cases | E19: 14 | F19: =IFERROR(INDEX(Categories!$B$5:$B$27,MATCH(E19,Categories!$A$5:$A$27,0)),"") -> Frontend | G19: Real-world scenarios or examples demonstrating how offerings are used | H19: IT | I19: Level 1 | J19: =IFERROR(INDEX(Rates!$D$6:$D$15,MATCH(H19&"|"&I19,Rates!$C$6:$C$15,0)),0) -> 100 | K19: 2 | L19: =K19*J19 -> 200
A20: 16 | C20: Homepage – Multi-Industry | D20: Industry Selector | E20: 14 | F20: =IFERROR(INDEX(Categories!$B$5:$B$27,MATCH(E20,Categories!$A$5:$A$27,0)),"") -> Frontend | G20: Selector for multiple industries | H20: IT | I20: Level 2 | J20: =IFERROR(INDEX(Rates!$D$6:$D$15,MATCH(H20&"|"&I20,Rates!$C$6:$C$15,0)),0) -> 120 | K20: 8 | L20: =K20*J20 -> 960 | M20: Hours scale with the number of industries. Confirm a cap in the quote.
A21: 17 | C21: Homepage – Multi-Industry | D21: Location Selector | E21: 14 | F21: =IFERROR(INDEX(Categories!$B$5:$B$27,MATCH(E21,Categories!$A$5:$A$27,0)),"") -> Frontend | G21: Selector for multiple branches/locations | H21: IT | I21: Level 2 | J21: =IFERROR(INDEX(Rates!$D$6:$D$15,MATCH(H21&"|"&I21,Rates!$C$6:$C$15,0)),0) -> 120 | K21: 8 | L21: =K21*J21 -> 960 | M21: Hours scale with the number of locations. Confirm a cap in the quote.
A22: 18 | C22: Homepage – Multi-Industry | D22: Dynamic Content Sections | E22: 14 | F22: =IFERROR(INDEX(Categories!$B$5:$B$27,MATCH(E22,Categories!$A$5:$A$27,0)),"") -> Frontend | G22: Conditional content per audience | H22: IT | I22: Level 2 | J22: =IFERROR(INDEX(Rates!$D$6:$D$15,MATCH(H22&"|"&I22,Rates!$C$6:$C$15,0)),0) -> 120 | K22: 10 | L22: =K22*J22 -> 1200 | M22: Each extra condition/rule adds testing time, not just build time.
A23: 19 | C23: Homepage – Multi-Industry | D23: Interactive Location Finder | E23: 15 | F23: =IFERROR(INDEX(Categories!$B$5:$B$27,MATCH(E23,Categories!$A$5:$A$27,0)),"") -> Integration | G23: Map or location-based finder for offices, stores, or service areas | H23: IT | I23: Level 2 | J23: =IFERROR(INDEX(Rates!$D$6:$D$15,MATCH(H23&"|"&I23,Rates!$C$6:$C$15,0)),0) -> 120 | K23: 12 | L23: =K23*J23 -> 1440 | M23: Excludes map API billing (Google Maps is metered). Radius search and geolocation add hours.
A24: 20 | C24: Homepage – Multi-Industry | D24: Multi-Audience Messaging | E24: 14 | F24: =IFERROR(INDEX(Categories!$B$5:$B$27,MATCH(E24,Categories!$A$5:$A$27,0)),"") -> Frontend | G24: Content tailored to different audience segments or user types | H24: IT | I24: Level 2 | J24: =IFERROR(INDEX(Rates!$D$6:$D$15,MATCH(H24&"|"&I24,Rates!$C$6:$C$15,0)),0) -> 120 | K24: 12 | L24: =K24*J24 -> 1440 | M24: Content writing for each segment is separate from the build.
A25: 21 | C25: Core Page - Standard | D25: Standard Page (About, Services) | E25: 14 | F25: =IFERROR(INDEX(Categories!$B$5:$B$27,MATCH(E25,Categories!$A$5:$A$27,0)),"") -> Frontend | G25: Standard Content Page (About, Services, etc.) | H25: IT | I25: Level 1 | J25: =IFERROR(INDEX(Rates!$D$6:$D$15,MATCH(H25&"|"&I25,Rates!$C$6:$C$15,0)),0) -> 100 | K25: 8 | L25: =K25*J25 -> 800 | M25: This is per page. Multiply by page count and confirm the total in the quote.
A26: 22 | C26: Core Page - Landing Page | D26: Conversion Page | E26: 14 | F26: =IFERROR(INDEX(Categories!$B$5:$B$27,MATCH(E26,Categories!$A$5:$A$27,0)),"") -> Frontend | G26: Conversion-focused landing page designed to drive specific user actions (e.g., lead generation or sales), including structured sections such as hero, benefits, social proof, and strong CTAs using a reusable layout. | H26: IT | I26: Level 1 | J26: =IFERROR(INDEX(Rates!$D$6:$D$15,MATCH(H26&"|"&I26,Rates!$C$6:$C$15,0)),0) -> 100 | K26: 8 | L26: =K26*J26 -> 800 | M26: Per page. Second and later landing pages using the same layout should be cheaper.
A27: 23 | C27: Core Page - Contact Page | D27: Form or contact details page | E27: 14 | F27: =IFERROR(INDEX(Categories!$B$5:$B$27,MATCH(E27,Categories!$A$5:$A$27,0)),"") -> Frontend | G27: Contact page including form setup and/or business contact details, with clear layout, validation, and user-friendly structure for inquiries or lead capture. | H27: IT | I27: Level 1 | J27: =IFERROR(INDEX(Rates!$D$6:$D$15,MATCH(H27&"|"&I27,Rates!$C$6:$C$15,0)),0) -> 100 | K27: 6 | L27: =K27*J27 -> 600 | M27: Includes one form. Map embed and multi-location contact info may add time.
A28: 24 | C28: Core Page - Detail Pages | D28: Detail Template | E28: 14 | F28: =IFERROR(INDEX(Categories!$B$5:$B$27,MATCH(E28,Categories!$A$5:$A$27,0)),"") -> Frontend | G28: Template-based detail page for individual content (e.g., blog posts or service pages), structured for readability, SEO, and consistent layout | H28: IT | I28: Level 1 | J28: =IFERROR(INDEX(Rates!$D$6:$D$15,MATCH(H28&"|"&I28,Rates!$C$6:$C$15,0)),0) -> 100 | K28: 6 | L28: =K28*J28 -> 600 | M28: Per template. Each additional content type usually needs its own template.
A29: 25 | C29: Homepage – Standard | D29: Forms Spam Protection (reCAPTCHA) | E29: 18 | F29: =IFERROR(INDEX(Categories!$B$5:$B$27,MATCH(E29,Categories!$A$5:$A$27,0)),"") -> Performance & Security | G29: Implement and configure reCAPTCHA (v2/v3) on all forms to prevent spam submissions. | H29: IT | I29: Level 1 | J29: =IFERROR(INDEX(Rates!$D$6:$D$15,MATCH(H29&"|"&I29,Rates!$C$6:$C$15,0)),0) -> 100 | K29: 1 | L29: =K29*J29 -> 100 | M29: Covers all forms at once. Honeypot or alternative spam tools may be quicker or slower.
A30: 26 | C30: Homepage – Advanced Dynamic | D30: Custom-Coded Blocks | E30: 14 | F30: =IFERROR(INDEX(Categories!$B$5:$B$27,MATCH(E30,Categories!$A$5:$A$27,0)),"") -> Frontend | G30: Custom reusable blocks | H30: IT | I30: Level 2 | J30: =IFERROR(INDEX(Rates!$D$6:$D$15,MATCH(H30&"|"&I30,Rates!$C$6:$C$15,0)),0) -> 120 | K30: 15 | L30: =K30*J30 -> 1800 | M30: Hours depend heavily on how many blocks. Define the block count in the quote.
A31: 27 | C31: Homepage – Advanced Dynamic | D31: Search Bar with Filters | E31: 14 | F31: =IFERROR(INDEX(Categories!$B$5:$B$27,MATCH(E31,Categories!$A$5:$A$27,0)),"") -> Frontend | G31: Advanced search and filter functionality | H31: IT | I31: Level 2 | J31: =IFERROR(INDEX(Rates!$D$6:$D$15,MATCH(H31&"|"&I31,Rates!$C$6:$C$15,0)),0) -> 120 | K31: 18 | L31: =K31*J31 -> 2160 | M31: AJAX filtering, large datasets, and combined filters all add significant time.
... A45: 41 | C45: Forms – Multi-Step | D45: Submission Handling | E45: 2 | F45: =IFERROR(INDEX(Categories!$B$5:$B$27,MATCH(E45,Categories!$A$5:$A$27,0)),"") -> Backend | G45: Store and process multi-step submissions | H45: IT | I45: Level 2 | J45: =IFERROR(INDEX(Rates!$D$6:$D$15,MATCH(H45&"|"&I45,Rates!$C$6:$C$15,0)),0) -> 120 | K45: 2 | L45: =K45*J45 -> 240 | M45: Partial-save and resume functionality would add substantially.
A46: 42 | B46: 37-40: Form Setup | C46: Forms – CRM Integration | D46: CRM API Setup | E46: 15 | F46: =IFERROR(INDEX(Categories!$B$5:$B$27,MATCH(E46,Categories!$A$5:$A$27,0)),"") -> Integration | G46: Connect form submissions to CRM | H46: IT | I46: Level 2 | J46: =IFERROR(INDEX(Rates!$D$6:$D$15,MATCH(H46&"|"&I46,Rates!$C$6:$C$15,0)),0) -> 120 | K46: 4 | L46: =K46*J46 -> 480 | M46: Assumes client provides CRM access and credentials. Delays here are common.
A47: 43 | B47: 37-40: Form Setup | C47: Forms – CRM Integration | D47: Data Mapping | E47: 15 | F47: =IFERROR(INDEX(Categories!$B$5:$B$27,MATCH(E47,Categories!$A$5:$A$27,0)),"") -> Integration | G47: Map form fields to CRM fields | H47: IT | I47: Level 2 | J47: =IFERROR(INDEX(Rates!$D$6:$D$15,MATCH(H47&"|"&I47,Rates!$C$6:$C$15,0)),0) -> 120 | K47: 2 | L47: =K47*J47 -> 240 | M47: Hours rise with field count and custom CRM objects.
A48: 44 | B48: 37-40: Form Setup | C48: Forms – CRM Integration | D48: Error Handling & Logging | E48: 15 | F48: =IFERROR(INDEX(Categories!$B$5:$B$27,MATCH(E48,Categories!$A$5:$A$27,0)),"") -> Integration | G48: Handle API errors and log submissions | H48: IT | I48: Level 2 | J48: =IFERROR(INDEX(Rates!$D$6:$D$15,MATCH(H48&"|"&I48,Rates!$C$6:$C$15,0)),0) -> 120 | K48: 2 | L48: =K48*J48 -> 240 | M48: Retry logic and admin alerts would add hours.
A49: 45 | C49: Integrations | D49: Appointment System | E49: 15 | F49: =IFERROR(INDEX(Categories!$B$5:$B$27,MATCH(E49,Categories!$A$5:$A$27,0)),"") -> Integration | G49: Booking and scheduling system. Plugin-based booking system (no custom development) | H49: IT | I49: Level 1 | J49: =IFERROR(INDEX(Rates!$D$6:$D$15,MATCH(H49&"|"&I49,Rates!$C$6:$C$15,0)),0) -> 100 | K49: 3 | L49: =K49*J49 -> 300 | M49: Excludes staff schedules, services, and availability data entry. That is Coordinator time.
A50: 46 | C50: Integrations | D50: Live Chat Integration | E50: 15 | F50: =IFERROR(INDEX(Categories!$B$5:$B$27,MATCH(E50,Categories!$A$5:$A$27,0)),"") -> Integration | G50: Embed live chat widget | H50: IT | I50: Level 1 | J50: =IFERROR(INDEX(Rates!$D$6:$D$15,MATCH(H50&"|"&I50,Rates!$C$6:$C$15,0)),0) -> 100 | K50: 2 | L50: =K50*J50 -> 200 | M50: Duplicate of task 36. Pick one and remove the other.
A51: 47 | C51: Integrations | D51: API Integration Basic | E51: 15 | F51: =IFERROR(INDEX(Categories!$B$5:$B$27,MATCH(E51,Categories!$A$5:$A$27,0)),"") -> Integration | G51: Simple API Integration | H51: IT | I51: Level 2 | J51: =IFERROR(INDEX(Rates!$D$6:$D$15,MATCH(H51&"|"&I51,Rates!$C$6:$C$15,0)),0) -> 120 | K51: 12 | L51: =K51*J51 -> 1440 | M51: Define 'basic' in writing: read-only, one endpoint, documented API.
A52: 48 | C52: Integrations | D52: API Integration Complex | E52: 15 | F52: =IFERROR(INDEX(Categories!$B$5:$B$27,MATCH(E52,Categories!$A$5:$A$27,0)),"") -> Integration | G52: Complex API Integration | H52: IT | I52: Level 2 | J52: =IFERROR(INDEX(Rates!$D$6:$D$15,MATCH(H52&"|"&I52,Rates!$C$6:$C$15,0)),0) -> 120 | K52: 25 | L52: =K52*J52 -> 3000 | M52: High overrun risk. Consider quoting a discovery block first, then the build.
A53: 49 | C53: Integrations | D53: Zapier Workflows | E53: 15 | F53: =IFERROR(INDEX(Categories!$B$5:$B$27,MATCH(E53,Categories!$A$5:$A$27,0)),"") -> Integration | G53: Automate workflows with Zapier | H53: IT | I53: Level 1 | J53: =IFERROR(INDEX(Rates!$D$6:$D$15,MATCH(H53&"|"&I53,Rates!$C$6:$C$15,0)),0) -> 100 | K53: 6 | L53: =K53*J53 -> 600 | M53: Priced per set of workflows. Note how many Zaps are included. Excludes Zapier subscription.
A54: 50 | C54: Integrations | D54: Accessibility (ADA) Basic | E54: 1 | F54: =IFERROR(INDEX(Categories!$B$5:$B$27,MATCH(E54,Categories!$A$5:$A$27,0)),"") -> Accessibility | G54: Essential fixes for usability (alt text, contrast, basic keyboard support) | H54: IT | I54: Level 1 | J54: =IFERROR(INDEX(Rates!$D$6:$D$15,MATCH(H54&"|"&I54,Rates!$C$6:$C$15,0)),0) -> 100 | K54: 6 | L54: =K54*J54 -> 600 | M54: Scales with page count. Alt text writing may be Creative or Coordinator time.
A55: 51 | C55: Integrations | D55: Accessibility (ADA) Strict Compliance | E55: 1 | F55: =IFERROR(INDEX(Categories!$B$5:$B$27,MATCH(E55,Categories!$A$5:$A$27,0)),"") -> Accessibility | G55: Full WCAG compliance with complete support and thorough testing | H55: IT | I55: Level 2 | J55: =IFERROR(INDEX(Rates!$D$6:$D$15,MATCH(H55&"|"&I55,Rates!$C$6:$C$15,0)),0) -> 120 | K55: 25 | L55: =K55*J55 -> 3000 | M55: Excludes third-party audit or certification. Never guarantee legal compliance in the quote.
...

Sheet Squarespace
A1: Task Pricing – Squarespace
A2: Base Hours unchanged. category_id has been remapped to the new Categories list.
A4: id | B4: Dependencies | C4: Module | D4: Name | E4: category_id | F4: Category | G4: Description | H4: Responsible | I4: Level | J4: Rate | K4: Base Hours | L4: Estimated Cost | M4: Hours – Things to Consider
A5: 1 | C5: Homepage – Standard | D5: Hero Section | E5: 14 | F5: =IFERROR(INDEX(Categories!$B$5:$B$27,MATCH(E5,Categories!$A$5:$A$27,0)),"") -> Frontend | G5: Hero section and headline | H5: IT | I5: Level 1 | J5: =IFERROR(INDEX(Rates!$D$6:$D$15,MATCH(H5&"|"&I5,Rates!$C$6:$C$15,0)),0) -> 100 | K5: 2 | L5: =K5*J5 -> 200
A6: 2 | C6: Homepage – Standard | D6: Services or Product Grid | E6: 14 | F6: =IFERROR(INDEX(Categories!$B$5:$B$27,MATCH(E6,Categories!$A$5:$A$27,0)),"") -> Frontend | G6: Grid layout using Squarespace sections or summary blocks | H6: IT | I6: Level 1 | J6: =IFERROR(INDEX(Rates!$D$6:$D$15,MATCH(H6&"|"&I6,Rates!$C$6:$C$15,0)),0) -> 100 | K6: 3 | L6: =K6*J6 -> 300 | M6: Assumes a fixed number of items. Dynamic, data-driven grids cost more.
A7: 3 | C7: Homepage – Standard | D7: Testimonials (Embed) | E7: 15 | F7: =IFERROR(INDEX(Categories!$B$5:$B$27,MATCH(E7,Categories!$A$5:$A$27,0)),"") -> Integration | G7: Testimonials via embed block or native content | H7: IT | I7: Level 1 | J7: =IFERROR(INDEX(Rates!$D$6:$D$15,MATCH(H7&"|"&I7,Rates!$C$6:$C$15,0)),0) -> 100 | K7: 3 | L7: =K7*J7 -> 300 | M7: Styling a third-party widget can take longer than expected if the platform limits CSS.
A8: 4 | C8: Homepage – Standard | D8: Team Preview | E8: 14 | F8: =IFERROR(INDEX(Categories!$B$5:$B$27,MATCH(E8,Categories!$A$5:$A$27,0)),"") -> Frontend | G8: Team member section using image + text blocks | H8: IT | I8: Level 1 | J8: =IFERROR(INDEX(Rates!$D$6:$D$15,MATCH(H8&"|"&I8,Rates!$C$6:$C$15,0)),0) -> 100 | K8: 1.5 | L8: =K8*J8 -> 150 | M8: Bios and photo cropping are content work, not build work.
A9: 5 | C9: Homepage – Standard | D9: Footer Layout | E9: 14 | F9: =IFERROR(INDEX(Categories!$B$5:$B$27,MATCH(E9,Categories!$A$5:$A$27,0)),"") -> Frontend | G9: Footer navigation, contact, social links | H9: IT | I9: Level 1 | J9: =IFERROR(INDEX(Rates!$D$6:$D$15,MATCH(H9&"|"&I9,Rates!$C$6:$C$15,0)),0) -> 100 | K9: 1.5 | L9: =K9*J9 -> 150 | M9: Mega-footers with multiple menus and a newsletter form run higher.
A10: 6 | C10: Homepage – Conversion | D10: Strong Hero Offer | E10: 14 | F10: =IFERROR(INDEX(Categories!$B$5:$B$27,MATCH(E10,Categories!$A$5:$A$27,0)),"") -> Frontend | G10: Hero with CTA using Squarespace buttons | H10: IT | I10: Level 1 | J10: =IFERROR(INDEX(Rates!$D$6:$D$15,MATCH(H10&"|"&I10,Rates!$C$6:$C$15,0)),0) -> 100 | K10: 4 | L10: =K10*J10 -> 400
A11: 7 | C11: Homepage – Conversion | D11: Benefits/Features | E11: 14 | F11: =IFERROR(INDEX(Categories!$B$5:$B$27,MATCH(E11,Categories!$A$5:$A$27,0)),"") -> Frontend | G11: Feature sections using layout blocks | H11: IT | I11: Level 1 | J11: =IFERROR(INDEX(Rates!$D$6:$D$15,MATCH(H11&"|"&I11,Rates!$C$6:$C$15,0)),0) -> 100 | K11: 3 | L11: =K11*J11 -> 300 | M11: Icon sourcing or custom icons may need Creative hours on top.
A12: 8 | C12: Homepage – Conversion | D12: Social Proof / Trust Badges | E12: 14 | F12: =IFERROR(INDEX(Categories!$B$5:$B$27,MATCH(E12,Categories!$A$5:$A$27,0)),"") -> Frontend | G12: Logos or badges using image blocks | H12: IT | I12: Level 1 | J12: =IFERROR(INDEX(Rates!$D$6:$D$15,MATCH(H12&"|"&I12,Rates!$C$6:$C$15,0)),0) -> 100 | K12: 2 | L12: =K12*J12 -> 200 | M12: Assumes client supplies logos in usable formats. Logo cleanup is Creative time.
A13: 9 | C13: Homepage – Conversion | D13: FAQ Section | E13: 14 | F13: =IFERROR(INDEX(Categories!$B$5:$B$27,MATCH(E13,Categories!$A$5:$A$27,0)),"") -> Frontend | G13: Collapsible FAQ blocks | H13: IT | I13: Level 1 | J13: =IFERROR(INDEX(Rates!$D$6:$D$15,MATCH(H13&"|"&I13,Rates!$C$6:$C$15,0)),0) -> 100 | K13: 2 | L13: =K13*J13 -> 200 | M13: Add a little time if FAQ schema markup is also required.
A14: 10 | C14: Homepage – Standard | D14: Pricing Tables | E14: 14 | F14: =IFERROR(INDEX(Categories!$B$5:$B$27,MATCH(E14,Categories!$A$5:$A$27,0)),"") -> Frontend | G14: Pricing using columns/layout blocks | H14: IT | I14: Level 1 | J14: =IFERROR(INDEX(Rates!$D$6:$D$15,MATCH(H14&"|"&I14,Rates!$C$6:$C$15,0)),0) -> 100 | K14: 4 | L14: =K14*J14 -> 400 | M14: No native pricing table. Built manually, so more than 3 plans adds time.
A15: 11 | C15: Homepage – Standard | D15: Galleries | E15: 14 | F15: =IFERROR(INDEX(Categories!$B$5:$B$27,MATCH(E15,Categories!$A$5:$A$27,0)),"") -> Frontend | G15: Gallery block (grid/slider/lightbox) | H15: IT | I15: Level 1 | J15: =IFERROR(INDEX(Rates!$D$6:$D$15,MATCH(H15&"|"&I15,Rates!$C$6:$C$15,0)),0) -> 100 | K15: 2 | L15: =K15*J15 -> 200 | M15: Per gallery. Image prep is billed separately.
A16: 12 | C16: Homepage – Standard | D16: Video Embeds | E16: 14 | F16: =IFERROR(INDEX(Categories!$B$5:$B$27,MATCH(E16,Categories!$A$5:$A$27,0)),"") -> Frontend | G16: Video block (YouTube/Vimeo) | H16: IT | I16: Level 1 | J16: =IFERROR(INDEX(Rates!$D$6:$D$15,MATCH(H16&"|"&I16,Rates!$C$6:$C$15,0)),0) -> 100 | K16: 1 | L16: =K16*J16 -> 100 | M16: Self-hosted video or custom players are a different, larger scope.
A17: 13 | C17: Homepage – Standard | D17: Donations / Payments | E17: 15 | F17: =IFERROR(INDEX(Categories!$B$5:$B$27,MATCH(E17,Categories!$A$5:$A$27,0)),"") -> Integration | G17: Squarespace Payments or Stripe integration | H17: IT | I17: Level 1 | J17: =IFERROR(INDEX(Rates!$D$6:$D$15,MATCH(H17&"|"&I17,Rates!$C$6:$C$15,0)),0) -> 100 | K17: 4 | L17: =K17*J17 -> 400 | M17: Excludes merchant account approval. Client delays here are common.
A18: 14 | C18: Homepage – Standard | D18: Use Cases | E18: 14 | F18: =IFERROR(INDEX(Categories!$B$5:$B$27,MATCH(E18,Categories!$A$5:$A$27,0)),"") -> Frontend | G18: Content sections for use cases | H18: IT | I18: Level 1 | J18: =IFERROR(INDEX(Rates!$D$6:$D$15,MATCH(H18&"|"&I18,Rates!$C$6:$C$15,0)),0) -> 100 | K18: 2 | L18: =K18*J18 -> 200
A19: 15 | C19: Homepage – Standard | D19: Forms Spam Protection | E19: 18 | F19: =IFERROR(INDEX(Categories!$B$5:$B$27,MATCH(E19,Categories!$A$5:$A$27,0)),"") -> Performance & Security | G19: Basic spam protection (Squarespace built-in) | H19: IT | I19: Level 1 | J19: =IFERROR(INDEX(Rates!$D$6:$D$15,MATCH(H19&"|"&I19,Rates!$C$6:$C$15,0)),0) -> 100 | K19: 1 | L19: =K19*J19 -> 100 | M19: Built-in only. You have far less control than on WordPress.
A20: 16 | C20: Homepage – Creative | D20: Full-Screen Visuals | E20: 14 | F20: =IFERROR(INDEX(Categories!$B$5:$B$27,MATCH(E20,Categories!$A$5:$A$27,0)),"") -> Frontend | G20: Full-width image sections | H20: Creative | I20: Level 1 | J20: =IFERROR(INDEX(Rates!$D$6:$D$15,MATCH(H20&"|"&I20,Rates!$C$6:$C$15,0)),0) -> 100 | K20: 6 | L20: =K20*J20 -> 600 | M20: Image sourcing, licensing, and retouching may be billed separately.
A21: 17 | C21: Homepage – Creative | D21: Parallax Effects | E21: 14 | F21: =IFERROR(INDEX(Categories!$B$5:$B$27,MATCH(E21,Categories!$A$5:$A$27,0)),"") -> Frontend | G21: Built-in scroll effects (limited vs WP) | H21: IT | I21: Level 2 | J21: =IFERROR(INDEX(Rates!$D$6:$D$15,MATCH(H21&"|"&I21,Rates!$C$6:$C$15,0)),0) -> 120 | K21: 3 | L21: =K21*J21 -> 360 | M21: Native effects only. Custom parallax needs code injection and a Business plan.
A22: 18 | C22: Homepage – Creative | D22: Hover Animations | E22: 14 | F22: =IFERROR(INDEX(Categories!$B$5:$B$27,MATCH(E22,Categories!$A$5:$A$27,0)),"") -> Frontend | G22: Basic hover effects (native styles) | H22: IT | I22: Level 1 | J22: =IFERROR(INDEX(Rates!$D$6:$D$15,MATCH(H22&"|"&I22,Rates!$C$6:$C$15,0)),0) -> 100 | K22: 2 | L22: =K22*J22 -> 200 | M22: Needs a touch-device fallback, which is easy to forget in the estimate.
A23: 19 | C23: Homepage – Creative | D23: Creative Layouts | E23: 14 | F23: =IFERROR(INDEX(Categories!$B$5:$B$27,MATCH(E23,Categories!$A$5:$A$27,0)),"") -> Frontend | G23: Custom section layouts using fluid engine | H23: IT | I23: Level 1 | J23: =IFERROR(INDEX(Rates!$D$6:$D$15,MATCH(H23&"|"&I23,Rates!$C$6:$C$15,0)),0) -> 100 | K23: 4 | L23: =K23*J23 -> 400 | M23: Fluid Engine desktop and mobile layouts are built separately.
A24: 20 | C24: Homepage – Creative | D24: Portfolio Preview | E24: 14 | F24: =IFERROR(INDEX(Categories!$B$5:$B$27,MATCH(E24,Categories!$A$5:$A$27,0)),"") -> Frontend | G24: Portfolio/gallery collection preview | H24: IT | I24: Level 1 | J24: =IFERROR(INDEX(Rates!$D$6:$D$15,MATCH(H24&"|"&I24,Rates!$C$6:$C$15,0)),0) -> 100 | K24: 4 | L24: =K24*J24 -> 400 | M24: Filtering by category adds hours.
A25: 21 | C25: Homepage – Conversion | D25: Lead Capture Form | E25: 14 | F25: =IFERROR(INDEX(Categories!$B$5:$B$27,MATCH(E25,Categories!$A$5:$A$27,0)),"") -> Frontend | G25: Squarespace form block | H25: IT | I25: Level 1 | J25: =IFERROR(INDEX(Rates!$D$6:$D$15,MATCH(H25&"|"&I25,Rates!$C$6:$C$15,0)),0) -> 100 | K25: 2 | L25: =K25*J25 -> 200 | M25: CRM connection is billed separately.
A26: 22 | C26: Integrations | D26: Live Chat Integration | E26: 15 | F26: =IFERROR(INDEX(Categories!$B$5:$B$27,MATCH(E26,Categories!$A$5:$A$27,0)),"") -> Integration | G26: Embed third-party chat (Intercom, etc.) | H26: IT | I26: Level 1 | J26: =IFERROR(INDEX(Rates!$D$6:$D$15,MATCH(H26&"|"&I26,Rates!$C$6:$C$15,0)),0) -> 100 | K26: 2 | L26: =K26*J26 -> 200 | M26: Requires a Business plan for code injection.
A27: 23 | C27: Integrations | D27: Appointment Scheduling | E27: 15 | F27: =IFERROR(INDEX(Categories!$B$5:$B$27,MATCH(E27,Categories!$A$5:$A$27,0)),"") -> Integration | G27: Squarespace Scheduling or embed tool | H27: IT | I27: Level 1 | J27: =IFERROR(INDEX(Rates!$D$6:$D$15,MATCH(H27&"|"&I27,Rates!$C$6:$C$15,0)),0) -> 100 | K27: 3 | L27: =K27*J27 -> 300 | M27: Excludes the Acuity subscription and entering services or availability.
A28: 24 | C28: Integrations | D28: Zapier Workflows | E28: 15 | F28: =IFERROR(INDEX(Categories!$B$5:$B$27,MATCH(E28,Categories!$A$5:$A$27,0)),"") -> Integration | G28: Zapier connection via form/email triggers | H28: IT | I28: Level 1 | J28: =IFERROR(INDEX(Rates!$D$6:$D$15,MATCH(H28&"|"&I28,Rates!$C$6:$C$15,0)),0) -> 100 | K28: 4 | L28: =K28*J28 -> 400 | M28: Note how many Zaps are included. Excludes the Zapier subscription.
A29: 25 | C29: Integrations | D29: Basic API / Embed Integration | E29: 15 | F29: =IFERROR(INDEX(Categories!$B$5:$B$27,MATCH(E29,Categories!$A$5:$A$27,0)),"") -> Integration | G29: Embed external tools via code block | H29: IT | I29: Level 2 | J29: =IFERROR(INDEX(Rates!$D$6:$D$15,MATCH(H29&"|"&I29,Rates!$C$6:$C$15,0)),0) -> 120 | K29: 6 | L29: =K29*J29 -> 720 | M29: Requires a Business plan for code injection.
A30: 26 | C30: Core Page - Standard | D30: Standard Page (About, Services) | E30: 14 | F30: =IFERROR(INDEX(Categories!$B$5:$B$27,MATCH(E30,Categories!$A$5:$A$27,0)),"") -> Frontend | G30: Basic pages using sections | H30: IT | I30: Level 1 | J30: =IFERROR(INDEX(Rates!$D$6:$D$15,MATCH(H30&"|"&I30,Rates!$C$6:$C$15,0)),0) -> 100 | K30: 6 | L30: =K30*J30 -> 600 | M30: Per page. Multiply by page count and confirm the total in the quote.
... A32: 28 | C32: Core Page - Contact Page | D32: Contact Page | E32: 14 | F32: =IFERROR(INDEX(Categories!$B$5:$B$27,MATCH(E32,Categories!$A$5:$A$27,0)),"") -> Frontend | G32: Form + contact info layout | H32: IT | I32: Level 1 | J32: =IFERROR(INDEX(Rates!$D$6:$D$15,MATCH(H32&"|"&I32,Rates!$C$6:$C$15,0)),0) -> 100 | K32: 5 | L32: =K32*J32 -> 500 | M32: Includes one form. Map embed and multi-location info may add time.
A33: 29 | C33: Core Page - Detail Page | D33: Blog/Service Detail | E33: 14 | F33: =IFERROR(INDEX(Categories!$B$5:$B$27,MATCH(E33,Categories!$A$5:$A$27,0)),"") -> Frontend | G33: Blog or collection item template | H33: IT | I33: Level 1 | J33: =IFERROR(INDEX(Rates!$D$6:$D$15,MATCH(H33&"|"&I33,Rates!$C$6:$C$15,0)),0) -> 100 | K33: 5 | L33: =K33*J33 -> 500
A34: 30 | C34: Forms – Standard | D34: Standard Form Setup | E34: 14 | F34: =IFERROR(INDEX(Categories!$B$5:$B$27,MATCH(E34,Categories!$A$5:$A$27,0)),"") -> Frontend | G34: Form with fields + email notifications | H34: IT | I34: Level 1 | J34: =IFERROR(INDEX(Rates!$D$6:$D$15,MATCH(H34&"|"&I34,Rates!$C$6:$C$15,0)),0) -> 100 | K34: 2 | L34: =K34*J34 -> 200 | M34: Priced per form. Confirm the form count before quoting.
A35: 31 | C35: Forms – Advanced | D35: Storage & Notifications | E35: 14 | F35: =IFERROR(INDEX(Categories!$B$5:$B$27,MATCH(E35,Categories!$A$5:$A$27,0)),"") -> Frontend | G35: Form submissions stored + email | H35: IT | I35: Level 1 | J35: =IFERROR(INDEX(Rates!$D$6:$D$15,MATCH(H35&"|"&I35,Rates!$C$6:$C$15,0)),0) -> 100 | K35: 2 | L35: =K35*J35 -> 200
A36: 32 | C36: Members Area | D36: Members Area Setup | E36: 2 | F36: =IFERROR(INDEX(Categories!$B$5:$B$27,MATCH(E36,Categories!$A$5:$A$27,0)),"") -> Backend | G36: Squarespace Member Areas setup | H36: IT | I36: Level 1 | J36: =IFERROR(INDEX(Rates!$D$6:$D$15,MATCH(H36&"|"&I36,Rates!$C$6:$C$15,0)),0) -> 100 | K36: 6 | L36: =K36*J36 -> 600 | M36: Requires the paid Member Areas add-on.
A37: 33 | C37: Members Area | D37: Basic Access Control | E37: 2 | F37: =IFERROR(INDEX(Categories!$B$5:$B$27,MATCH(E37,Categories!$A$5:$A$27,0)),"") -> Backend | G37: Restrict pages/content | H37: IT | I37: Level 1 | J37: =IFERROR(INDEX(Rates!$D$6:$D$15,MATCH(H37&"|"&I37,Rates!$C$6:$C$15,0)),0) -> 100 | K37: 4 | L37: =K37*J37 -> 400 | M37: Far less flexible than WordPress roles. Set expectations.
A38: 34 | C38: E-Commerce | D38: Product Listings | E38: 12 | F38: =IFERROR(INDEX(Categories!$B$5:$B$27,MATCH(E38,Categories!$A$5:$A$27,0)),"") -> E-Commerce | G38: Product collection setup | H38: IT | I38: Level 1 | J38: =IFERROR(INDEX(Rates!$D$6:$D$15,MATCH(H38&"|"&I38,Rates!$C$6:$C$15,0)),0) -> 100 | K38: 5 | L38: =K38*J38 -> 500 | M38: Setup only. Per-product data entry is separate and often underestimated.
A39: 35 | C39: E-Commerce | D39: Product Detail Page | E39: 12 | F39: =IFERROR(INDEX(Categories!$B$5:$B$27,MATCH(E39,Categories!$A$5:$A$27,0)),"") -> E-Commerce | G39: Product page layout | H39: IT | I39: Level 1 | J39: =IFERROR(INDEX(Rates!$D$6:$D$15,MATCH(H39&"|"&I39,Rates!$C$6:$C$15,0)),0) -> 100 | K39: 5 | L39: =K39*J39 -> 500
A40: 36 | C40: E-Commerce | D40: Cart Functionality | E40: 12 | F40: =IFERROR(INDEX(Categories!$B$5:$B$27,MATCH(E40,Categories!$A$5:$A$27,0)),"") -> E-Commerce | G40: Built-in cart | H40: IT | I40: Level 1 | J40: =IFERROR(INDEX(Rates!$D$6:$D$15,MATCH(H40&"|"&I40,Rates!$C$6:$C$15,0)),0) -> 100 | K40: 3 | L40: =K40*J40 -> 300 | M40: Mini-cart and AJAX cart customization add hours.
A41: 37 | C41: E-Commerce | D41: Checkout Flow | E41: 12 | F41: =IFERROR(INDEX(Categories!$B$5:$B$27,MATCH(E41,Categories!$A$5:$A$27,0)),"") -> E-Commerce | G41: Native checkout | H41: IT | I41: Level 1 | J41: =IFERROR(INDEX(Rates!$D$6:$D$15,MATCH(H41&"|"&I41,Rates!$C$6:$C$15,0)),0) -> 100 | K41: 4 | L41: =K41*J41 -> 400 | M41: Native checkout is largely locked. Limited custom fields.
A42: 38 | C42: E-Commerce | D42: Payments Setup | E42: 12 | F42: =IFERROR(INDEX(Categories!$B$5:$B$27,MATCH(E42,Categories!$A$5:$A$27,0)),"") -> E-Commerce | G42: Stripe/PayPal via Squarespace | H42: IT | I42: Level 1 | J42: =IFERROR(INDEX(Rates!$D$6:$D$15,MATCH(H42&"|"&I42,Rates!$C$6:$C$15,0)),0) -> 100 | K42: 3 | L42: =K42*J42 -> 300 | M42: Excludes merchant account approval. Client delays are common.
...

Sheet Shopify
A1: Task Pricing – Shopify
A2: Base Hours unchanged. category_id has been remapped to the new Categories list.
A4: id | B4: Dependencies | C4: Module | D4: Name | E4: category_id | F4: Category | G4: Description | H4: Responsible | I4: Level | J4: Rate | K4: Base Hours | L4: Estimated Cost | M4: Hours – Things to Consider
A5: 1 | C5: Homepage – Standard | D5: Hero Section | E5: 14 | F5: =IFERROR(INDEX(Categories!$B$5:$B$27,MATCH(E5,Categories!$A$5:$A$27,0)),"") -> Frontend | G5: Hero section and headline | H5: IT | I5: Level 1 | J5: =IFERROR(INDEX(Rates!$D$6:$D$15,MATCH(H5&"|"&I5,Rates!$C$6:$C$15,0)),0) -> 100 | K5: 2 | L5: =K5*J5 -> 200
A6: 2 | C6: Homepage – Standard | D6: Services or Product Grid | E6: 14 | F6: =IFERROR(INDEX(Categories!$B$5:$B$27,MATCH(E6,Categories!$A$5:$A$27,0)),"") -> Frontend | G6: Product/collection grid using Shopify sections | H6: IT | I6: Level 1 | J6: =IFERROR(INDEX(Rates!$D$6:$D$15,MATCH(H6&"|"&I6,Rates!$C$6:$C$15,0)),0) -> 100 | K6: 3 | L6: =K6*J6 -> 300 | M6: Assumes a fixed number of items. Dynamic, data-driven grids cost more.
A7: 3 | C7: Homepage – Standard | D7: Testimonials | E7: 15 | F7: =IFERROR(INDEX(Categories!$B$5:$B$27,MATCH(E7,Categories!$A$5:$A$27,0)),"") -> Integration | G7: Testimonials via theme section or app | H7: IT | I7: Level 1 | J7: =IFERROR(INDEX(Rates!$D$6:$D$15,MATCH(H7&"|"&I7,Rates!$C$6:$C$15,0)),0) -> 100 | K7: 3 | L7: =K7*J7 -> 300 | M7: Styling a third-party widget or app can take longer than expected.
A8: 4 | C8: Homepage – Standard | D8: Team Preview | E8: 14 | F8: =IFERROR(INDEX(Categories!$B$5:$B$27,MATCH(E8,Categories!$A$5:$A$27,0)),"") -> Frontend | G8: Team section using content blocks | H8: IT | I8: Level 1 | J8: =IFERROR(INDEX(Rates!$D$6:$D$15,MATCH(H8&"|"&I8,Rates!$C$6:$C$15,0)),0) -> 100 | K8: 2 | L8: =K8*J8 -> 200 | M8: Bios and photo cropping are content work, not build work.
A9: 5 | C9: Homepage – Standard | D9: Footer Layout | E9: 14 | F9: =IFERROR(INDEX(Categories!$B$5:$B$27,MATCH(E9,Categories!$A$5:$A$27,0)),"") -> Frontend | G9: Footer with navigation, contact, socials | H9: IT | I9: Level 1 | J9: =IFERROR(INDEX(Rates!$D$6:$D$15,MATCH(H9&"|"&I9,Rates!$C$6:$C$15,0)),0) -> 100 | K9: 2 | L9: =K9*J9 -> 200 | M9: Mega-footers with multiple menus and a newsletter form run higher.
A10: 6 | C10: Homepage – Conversion | D10: Strong Hero Offer | E10: 14 | F10: =IFERROR(INDEX(Categories!$B$5:$B$27,MATCH(E10,Categories!$A$5:$A$27,0)),"") -> Frontend | G10: Hero with CTA | H10: IT | I10: Level 1 | J10: =IFERROR(INDEX(Rates!$D$6:$D$15,MATCH(H10&"|"&I10,Rates!$C$6:$C$15,0)),0) -> 100 | K10: 4 | L10: =K10*J10 -> 400
A11: 7 | C11: Homepage – Conversion | D11: Benefits/Features | E11: 14 | F11: =IFERROR(INDEX(Categories!$B$5:$B$27,MATCH(E11,Categories!$A$5:$A$27,0)),"") -> Frontend | G11: Features/benefits sections | H11: IT | I11: Level 1 | J11: =IFERROR(INDEX(Rates!$D$6:$D$15,MATCH(H11&"|"&I11,Rates!$C$6:$C$15,0)),0) -> 100 | K11: 3 | L11: =K11*J11 -> 300 | M11: Icon sourcing or custom icons may need Creative hours on top.
A12: 8 | C12: Homepage – Conversion | D12: Social Proof / Trust Badges | E12: 14 | F12: =IFERROR(INDEX(Categories!$B$5:$B$27,MATCH(E12,Categories!$A$5:$A$27,0)),"") -> Frontend | G12: Logos, reviews, trust badges | H12: IT | I12: Level 1 | J12: =IFERROR(INDEX(Rates!$D$6:$D$15,MATCH(H12&"|"&I12,Rates!$C$6:$C$15,0)),0) -> 100 | K12: 2 | L12: =K12*J12 -> 200 | M12: Assumes client supplies logos in usable formats. Logo cleanup is Creative time.
A13: 9 | C13: Homepage – Conversion | D13: FAQ Section | E13: 14 | F13: =IFERROR(INDEX(Categories!$B$5:$B$27,MATCH(E13,Categories!$A$5:$A$27,0)),"") -> Frontend | G13: Accordion FAQ | H13: IT | I13: Level 1 | J13: =IFERROR(INDEX(Rates!$D$6:$D$15,MATCH(H13&"|"&I13,Rates!$C$6:$C$15,0)),0) -> 100 | K13: 2 | L13: =K13*J13 -> 200 | M13: Add a little time if FAQ schema markup is also required.
A14: 10 | C14: Homepage – Conversion | D14: Pricing Tables | E14: 14 | F14: =IFERROR(INDEX(Categories!$B$5:$B$27,MATCH(E14,Categories!$A$5:$A$27,0)),"") -> Frontend | G14: Subscription or pricing layouts | H14: IT | I14: Level 1 | J14: =IFERROR(INDEX(Rates!$D$6:$D$15,MATCH(H14&"|"&I14,Rates!$C$6:$C$15,0)),0) -> 100 | K14: 4 | L14: =K14*J14 -> 400 | M14: Monthly/annual toggles or more than 3 plans push this higher.
A15: 11 | C15: Homepage – E-Commerce | D15: Featured Products | E15: 12 | F15: =IFERROR(INDEX(Categories!$B$5:$B$27,MATCH(E15,Categories!$A$5:$A$27,0)),"") -> E-Commerce | G15: Featured products section | H15: IT | I15: Level 1 | J15: =IFERROR(INDEX(Rates!$D$6:$D$15,MATCH(H15&"|"&I15,Rates!$C$6:$C$15,0)),0) -> 100 | K15: 4 | L15: =K15*J15 -> 400
A16: 12 | C16: Homepage – E-Commerce | D16: Sales Banners | E16: 12 | F16: =IFERROR(INDEX(Categories!$B$5:$B$27,MATCH(E16,Categories!$A$5:$A$27,0)),"") -> E-Commerce | G16: Promo banners | H16: Creative | I16: Level 1 | J16: =IFERROR(INDEX(Rates!$D$6:$D$15,MATCH(H16&"|"&I16,Rates!$C$6:$C$15,0)),0) -> 100 | K16: 3 | L16: =K16*J16 -> 300 | M16: Recurring campaign artwork is worth a separate maintenance line item.
A17: 13 | C17: Homepage – E-Commerce | D17: Dynamic Product Feeds | E17: 12 | F17: =IFERROR(INDEX(Categories!$B$5:$B$27,MATCH(E17,Categories!$A$5:$A$27,0)),"") -> E-Commerce | G17: Collections + filters | H17: IT | I17: Level 1 | J17: =IFERROR(INDEX(Rates!$D$6:$D$15,MATCH(H17&"|"&I17,Rates!$C$6:$C$15,0)),0) -> 100 | K17: 6 | L17: =K17*J17 -> 600 | M17: Feeds to Google Merchant Center or Meta have their own spec requirements.
A18: 14 | C18: Homepage – E-Commerce | D18: Category Highlights | E18: 12 | F18: =IFERROR(INDEX(Categories!$B$5:$B$27,MATCH(E18,Categories!$A$5:$A$27,0)),"") -> E-Commerce | G18: Collection highlights | H18: IT | I18: Level 1 | J18: =IFERROR(INDEX(Rates!$D$6:$D$15,MATCH(H18&"|"&I18,Rates!$C$6:$C$15,0)),0) -> 100 | K18: 4 | L18: =K18*J18 -> 400
A19: 15 | C19: Homepage – E-Commerce | D19: Customer Reviews | E19: 12 | F19: =IFERROR(INDEX(Categories!$B$5:$B$27,MATCH(E19,Categories!$A$5:$A$27,0)),"") -> E-Commerce | G19: Product reviews via app | H19: IT | I19: Level 1 | J19: =IFERROR(INDEX(Rates!$D$6:$D$15,MATCH(H19&"|"&I19,Rates!$C$6:$C$15,0)),0) -> 100 | K19: 5 | L19: =K19*J19 -> 500 | M19: Excludes the review app subscription.
A20: 16 | C20: Homepage – E-Commerce | D20: Personalization Blocks | E20: 12 | F20: =IFERROR(INDEX(Categories!$B$5:$B$27,MATCH(E20,Categories!$A$5:$A$27,0)),"") -> E-Commerce | G20: Recommended products (apps) | H20: IT | I20: Level 2 | J20: =IFERROR(INDEX(Rates!$D$6:$D$15,MATCH(H20&"|"&I20,Rates!$C$6:$C$15,0)),0) -> 120 | K20: 6 | L20: =K20*J20 -> 720 | M20: Excludes the recommendation app subscription.
A21: 17 | C21: Homepage – Creative | D21: Full-Screen Visuals | E21: 14 | F21: =IFERROR(INDEX(Categories!$B$5:$B$27,MATCH(E21,Categories!$A$5:$A$27,0)),"") -> Frontend | G21: Image-heavy layouts | H21: Creative | I21: Level 1 | J21: =IFERROR(INDEX(Rates!$D$6:$D$15,MATCH(H21&"|"&I21,Rates!$C$6:$C$15,0)),0) -> 100 | K21: 5 | L21: =K21*J21 -> 500 | M21: Image sourcing, licensing, and retouching may be billed separately.
A22: 18 | C22: Homepage – Creative | D22: Parallax Effects | E22: 14 | F22: =IFERROR(INDEX(Categories!$B$5:$B$27,MATCH(E22,Categories!$A$5:$A$27,0)),"") -> Frontend | G22: Theme-based effects | H22: IT | I22: Level 2 | J22: =IFERROR(INDEX(Rates!$D$6:$D$15,MATCH(H22&"|"&I22,Rates!$C$6:$C$15,0)),0) -> 120 | K22: 3 | L22: =K22*J22 -> 360 | M22: Theme-dependent. A theme without support needs custom code.
A23: 19 | C23: Homepage – Creative | D23: Hover Animations | E23: 14 | F23: =IFERROR(INDEX(Categories!$B$5:$B$27,MATCH(E23,Categories!$A$5:$A$27,0)),"") -> Frontend | G23: Theme/custom CSS | H23: IT | I23: Level 1 | J23: =IFERROR(INDEX(Rates!$D$6:$D$15,MATCH(H23&"|"&I23,Rates!$C$6:$C$15,0)),0) -> 100 | K23: 3 | L23: =K23*J23 -> 300 | M23: Needs a touch-device fallback, which is easy to forget in the estimate.
A24: 20 | C24: Homepage – Creative | D24: Creative Layouts | E24: 14 | F24: =IFERROR(INDEX(Categories!$B$5:$B$27,MATCH(E24,Categories!$A$5:$A$27,0)),"") -> Frontend | G24: Custom sections or Liquid edits | H24: IT | I24: Level 1 | J24: =IFERROR(INDEX(Rates!$D$6:$D$15,MATCH(H24&"|"&I24,Rates!$C$6:$C$15,0)),0) -> 100 | K24: 5 | L24: =K24*J24 -> 500 | M24: Liquid edits mean theme-update risk later. Note that in the quote.
A25: 21 | C25: Homepage – Conversion | D25: Lead Capture Form | E25: 14 | F25: =IFERROR(INDEX(Categories!$B$5:$B$27,MATCH(E25,Categories!$A$5:$A$27,0)),"") -> Frontend | G25: Form or email signup | H25: IT | I25: Level 1 | J25: =IFERROR(INDEX(Rates!$D$6:$D$15,MATCH(H25&"|"&I25,Rates!$C$6:$C$15,0)),0) -> 100 | K25: 2 | L25: =K25*J25 -> 200 | M25: CRM connection is billed separately.
A26: 22 | C26: Homepage – Conversion | D26: Forms Spam Protection | E26: 18 | F26: =IFERROR(INDEX(Categories!$B$5:$B$27,MATCH(E26,Categories!$A$5:$A$27,0)),"") -> Performance & Security | G26: Basic spam protection | H26: IT | I26: Level 1 | J26: =IFERROR(INDEX(Rates!$D$6:$D$15,MATCH(H26&"|"&I26,Rates!$C$6:$C$15,0)),0) -> 100 | K26: 1 | L26: =K26*J26 -> 100 | M26: Covers all forms at once.
A27: 23 | C27: Core Page - Standard | D27: Standard Page (About, Services) | E27: 14 | F27: =IFERROR(INDEX(Categories!$B$5:$B$27,MATCH(E27,Categories!$A$5:$A$27,0)),"") -> Frontend | G27: Content pages | H27: IT | I27: Level 1 | J27: =IFERROR(INDEX(Rates!$D$6:$D$15,MATCH(H27&"|"&I27,Rates!$C$6:$C$15,0)),0) -> 100 | K27: 6 | L27: =K27*J27 -> 600 | M27: Per page. Multiply by page count and confirm the total in the quote.
A28: 24 | C28: Core Page - Landing Page | D28: Landing Page | E28: 14 | F28: =IFERROR(INDEX(Categories!$B$5:$B$27,MATCH(E28,Categories!$A$5:$A$27,0)),"") -> Frontend | G28: Conversion-focused layout | H28: IT | I28: Level 1 | J28: =IFERROR(INDEX(Rates!$D$6:$D$15,MATCH(H28&"|"&I28,Rates!$C$6:$C$15,0)),0) -> 100 | K28: 8 | L28: =K28*J28 -> 800 | M28: Per page. Second and later pages using the same layout should be cheaper.
A29: 25 | C29: Core Page - Contact Page | D29: Contact Page | E29: 14 | F29: =IFERROR(INDEX(Categories!$B$5:$B$27,MATCH(E29,Categories!$A$5:$A$27,0)),"") -> Frontend | G29: Contact form + info | H29: IT | I29: Level 1 | J29: =IFERROR(INDEX(Rates!$D$6:$D$15,MATCH(H29&"|"&I29,Rates!$C$6:$C$15,0)),0) -> 100 | K29: 5 | L29: =K29*J29 -> 500 | M29: Includes one form. Map embed and multi-location info may add time.
A30: 26 | C30: Core Page - Blog Detail | D30: Blog Post Template | E30: 22 | F30: =IFERROR(INDEX(Categories!$B$5:$B$27,MATCH(E30,Categories!$A$5:$A$27,0)),"") -> SEO & Content | G30: Shopify blog template | H30: IT | I30: Level 1 | J30: =IFERROR(INDEX(Rates!$D$6:$D$15,MATCH(H30&"|"&I30,Rates!$C$6:$C$15,0)),0) -> 100 | K30: 4 | L30: =K30*J30 -> 400 | M30: Related posts, author boxes, and share buttons add time.
... A38: 34 | C38: Integrations | D38: Accessibility (Basic) | E38: 1 | F38: =IFERROR(INDEX(Categories!$B$5:$B$27,MATCH(E38,Categories!$A$5:$A$27,0)),"") -> Accessibility | G38: Theme adjustments | H38: IT | I38: Level 1 | J38: =IFERROR(INDEX(Rates!$D$6:$D$15,MATCH(H38&"|"&I38,Rates!$C$6:$C$15,0)),0) -> 100 | K38: 5 | L38: =K38*J38 -> 500 | M38: Scales with page count. Never guarantee legal compliance.
A39: 35 | C39: Members / Accounts | D39: Customer Accounts | E39: 2 | F39: =IFERROR(INDEX(Categories!$B$5:$B$27,MATCH(E39,Categories!$A$5:$A$27,0)),"") -> Backend | G39: Shopify customer accounts | H39: IT | I39: Level 1 | J39: =IFERROR(INDEX(Rates!$D$6:$D$15,MATCH(H39&"|"&I39,Rates!$C$6:$C$15,0)),0) -> 100 | K39: 4 | L39: =K39*J39 -> 400
A40: 36 | C40: Members / Accounts | D40: Profile Management | E40: 2 | F40: =IFERROR(INDEX(Categories!$B$5:$B$27,MATCH(E40,Categories!$A$5:$A$27,0)),"") -> Backend | G40: Account editing | H40: IT | I40: Level 1 | J40: =IFERROR(INDEX(Rates!$D$6:$D$15,MATCH(H40&"|"&I40,Rates!$C$6:$C$15,0)),0) -> 100 | K40: 4 | L40: =K40*J40 -> 400 | M40: Custom profile fields and avatar uploads add hours.
A41: 37 | C41: Members / Accounts | D41: Restricted Content | E41: 2 | F41: =IFERROR(INDEX(Categories!$B$5:$B$27,MATCH(E41,Categories!$A$5:$A$27,0)),"") -> Backend | G41: Apps or Liquid logic | H41: IT | I41: Level 1 | J41: =IFERROR(INDEX(Rates!$D$6:$D$15,MATCH(H41&"|"&I41,Rates!$C$6:$C$15,0)),0) -> 100 | K41: 6 | L41: =K41*J41 -> 600 | M41: Needs an app or Liquid workarounds. Shopify is not built for this.
A42: 38 | C42: E-Commerce Core | D42: Product Template | E42: 12 | F42: =IFERROR(INDEX(Categories!$B$5:$B$27,MATCH(E42,Categories!$A$5:$A$27,0)),"") -> E-Commerce | G42: Product page template | H42: IT | I42: Level 1 | J42: =IFERROR(INDEX(Rates!$D$6:$D$15,MATCH(H42&"|"&I42,Rates!$C$6:$C$15,0)),0) -> 100 | K42: 6 | L42: =K42*J42 -> 600 | M42: One template. Simple and variable products may need different treatments.
A43: 39 | C43: E-Commerce Core | D43: Cart Functionality | E43: 12 | F43: =IFERROR(INDEX(Categories!$B$5:$B$27,MATCH(E43,Categories!$A$5:$A$27,0)),"") -> E-Commerce | G43: Built-in cart | H43: IT | I43: Level 1 | J43: =IFERROR(INDEX(Rates!$D$6:$D$15,MATCH(H43&"|"&I43,Rates!$C$6:$C$15,0)),0) -> 100 | K43: 4 | L43: =K43*J43 -> 400 | M43: Mini-cart and AJAX cart customization add hours.
A44: 40 | C44: E-Commerce Core | D44: Checkout Flow | E44: 12 | F44: =IFERROR(INDEX(Categories!$B$5:$B$27,MATCH(E44,Categories!$A$5:$A$27,0)),"") -> E-Commerce | G44: Shopify checkout (limited customization) | H44: IT | I44: Level 1 | J44: =IFERROR(INDEX(Rates!$D$6:$D$15,MATCH(H44&"|"&I44,Rates!$C$6:$C$15,0)),0) -> 100 | K44: 4 | L44: =K44*J44 -> 400 | M44: Checkout is locked unless the client is on Shopify Plus. Set expectations early.
A45: 41 | C45: E-Commerce Core | D45: Shipping Rules | E45: 12 | F45: =IFERROR(INDEX(Categories!$B$5:$B$27,MATCH(E45,Categories!$A$5:$A$27,0)),"") -> E-Commerce | G45: Shipping setup | H45: IT | I45: Level 1 | J45: =IFERROR(INDEX(Rates!$D$6:$D$15,MATCH(H45&"|"&I45,Rates!$C$6:$C$15,0)),0) -> 100 | K45: 4 | L45: =K45*J45 -> 400 | M45: Live carrier rates are more work than flat-rate zones.
A46: 42 | C46: E-Commerce Core | D46: Payment Gateway Integration | E46: 12 | F46: =IFERROR(INDEX(Categories!$B$5:$B$27,MATCH(E46,Categories!$A$5:$A$27,0)),"") -> E-Commerce | G46: Shopify Payments / PayPal | H46: IT | I46: Level 1 | J46: =IFERROR(INDEX(Rates!$D$6:$D$15,MATCH(H46&"|"&I46,Rates!$C$6:$C$15,0)),0) -> 100 | K46: 3 | L46: =K46*J46 -> 300 | M46: Excludes merchant account approval. Client delays are common.
A47: 43 | C47: E-Commerce Core | D47: Tax Calculator | E47: 12 | F47: =IFERROR(INDEX(Categories!$B$5:$B$27,MATCH(E47,Categories!$A$5:$A$27,0)),"") -> E-Commerce | G47: Built-in taxes | H47: IT | I47: Level 1 | J47: =IFERROR(INDEX(Rates!$D$6:$D$15,MATCH(H47&"|"&I47,Rates!$C$6:$C$15,0)),0) -> 100 | K47: 2 | L47: =K47*J47 -> 200 | M47: Built-in. Multi-jurisdiction tax may need Avalara or similar.
A48: 44 | C48: Advanced E-Commerce | D48: Product Options / Variants | E48: 12 | F48: =IFERROR(INDEX(Categories!$B$5:$B$27,MATCH(E48,Categories!$A$5:$A$27,0)),"") -> E-Commerce | G48: Variants or apps | H48: IT | I48: Level 1 | J48: =IFERROR(INDEX(Rates!$D$6:$D$15,MATCH(H48&"|"&I48,Rates!$C$6:$C$15,0)),0) -> 100 | K48: 6 | L48: =K48*J48 -> 600 | M48: Setup only, not per-product entry. Multiply by product count separately.
...

Sheet WIX
A1: Task Pricing – WIX
A2: Base Hours unchanged. category_id has been remapped to the new Categories list.
A4: id | B4: Dependencies | C4: Module | D4: Name | E4: category_id | F4: Category | G4: Description | H4: Responsible | I4: Level | J4: Rate | K4: Base Hours | L4: Estimated Cost | M4: Hours – Things to Consider
A5: 1 | C5: Homepage – Standard | D5: Hero Section | E5: 14 | F5: =IFERROR(INDEX(Categories!$B$5:$B$27,MATCH(E5,Categories!$A$5:$A$27,0)),"") -> Frontend | G5: Hero section and headline | H5: IT | I5: Level 1 | J5: =IFERROR(INDEX(Rates!$D$6:$D$15,MATCH(H5&"|"&I5,Rates!$C$6:$C$15,0)),0) -> 100 | K5: 2 | L5: =K5*J5 -> 200
A6: 2 | C6: Homepage – Standard | D6: Services or Product Grid | E6: 14 | F6: =IFERROR(INDEX(Categories!$B$5:$B$27,MATCH(E6,Categories!$A$5:$A$27,0)),"") -> Frontend | G6: Grid using Wix repeater/layout tools | H6: IT | I6: Level 1 | J6: =IFERROR(INDEX(Rates!$D$6:$D$15,MATCH(H6&"|"&I6,Rates!$C$6:$C$15,0)),0) -> 100 | K6: 3 | L6: =K6*J6 -> 300 | M6: Assumes a fixed number of items. Dynamic, data-driven grids cost more.
A7: 3 | C7: Homepage – Standard | D7: Testimonials | E7: 15 | F7: =IFERROR(INDEX(Categories!$B$5:$B$27,MATCH(E7,Categories!$A$5:$A$27,0)),"") -> Integration | G7: Testimonials via sections or apps | H7: IT | I7: Level 1 | J7: =IFERROR(INDEX(Rates!$D$6:$D$15,MATCH(H7&"|"&I7,Rates!$C$6:$C$15,0)),0) -> 100 | K7: 3 | L7: =K7*J7 -> 300 | M7: Styling a third-party widget or app can take longer than expected.
A8: 4 | C8: Homepage – Standard | D8: Team Preview | E8: 14 | F8: =IFERROR(INDEX(Categories!$B$5:$B$27,MATCH(E8,Categories!$A$5:$A$27,0)),"") -> Frontend | G8: Team section using repeaters | H8: IT | I8: Level 1 | J8: =IFERROR(INDEX(Rates!$D$6:$D$15,MATCH(H8&"|"&I8,Rates!$C$6:$C$15,0)),0) -> 100 | K8: 2 | L8: =K8*J8 -> 200 | M8: Bios and photo cropping are content work, not build work.
A9: 5 | C9: Homepage – Standard | D9: Footer Layout | E9: 14 | F9: =IFERROR(INDEX(Categories!$B$5:$B$27,MATCH(E9,Categories!$A$5:$A$27,0)),"") -> Frontend | G9: Footer with nav, contact, socials | H9: IT | I9: Level 1 | J9: =IFERROR(INDEX(Rates!$D$6:$D$15,MATCH(H9&"|"&I9,Rates!$C$6:$C$15,0)),0) -> 100 | K9: 2 | L9: =K9*J9 -> 200 | M9: Mega-footers with multiple menus and a newsletter form run higher.
A10: 6 | C10: Homepage – Conversion | D10: Strong Hero Offer | E10: 14 | F10: =IFERROR(INDEX(Categories!$B$5:$B$27,MATCH(E10,Categories!$A$5:$A$27,0)),"") -> Frontend | G10: Hero with CTA | H10: IT | I10: Level 1 | J10: =IFERROR(INDEX(Rates!$D$6:$D$15,MATCH(H10&"|"&I10,Rates!$C$6:$C$15,0)),0) -> 100 | K10: 4 | L10: =K10*J10 -> 400
A11: 7 | C11: Homepage – Conversion | D11: Benefits/Features | E11: 14 | F11: =IFERROR(INDEX(Categories!$B$5:$B$27,MATCH(E11,Categories!$A$5:$A$27,0)),"") -> Frontend | G11: Content sections | H11: IT | I11: Level 1 | J11: =IFERROR(INDEX(Rates!$D$6:$D$15,MATCH(H11&"|"&I11,Rates!$C$6:$C$15,0)),0) -> 100 | K11: 3 | L11: =K11*J11 -> 300 | M11: Icon sourcing or custom icons may need Creative hours on top.
A12: 8 | C12: Homepage – Conversion | D12: Social Proof / Trust Badges | E12: 14 | F12: =IFERROR(INDEX(Categories!$B$5:$B$27,MATCH(E12,Categories!$A$5:$A$27,0)),"") -> Frontend | G12: Logos/reviews | H12: IT | I12: Level 1 | J12: =IFERROR(INDEX(Rates!$D$6:$D$15,MATCH(H12&"|"&I12,Rates!$C$6:$C$15,0)),0) -> 100 | K12: 2 | L12: =K12*J12 -> 200 | M12: Assumes client supplies logos in usable formats. Logo cleanup is Creative time.
A13: 9 | C13: Homepage – Conversion | D13: FAQ Section | E13: 14 | F13: =IFERROR(INDEX(Categories!$B$5:$B$27,MATCH(E13,Categories!$A$5:$A$27,0)),"") -> Frontend | G13: Collapsible FAQ | H13: IT | I13: Level 1 | J13: =IFERROR(INDEX(Rates!$D$6:$D$15,MATCH(H13&"|"&I13,Rates!$C$6:$C$15,0)),0) -> 100 | K13: 2 | L13: =K13*J13 -> 200 | M13: Add a little time if FAQ schema markup is also required.
A14: 10 | C14: Homepage – Standard | D14: Pricing Tables | E14: 14 | F14: =IFERROR(INDEX(Categories!$B$5:$B$27,MATCH(E14,Categories!$A$5:$A$27,0)),"") -> Frontend | G14: Pricing layout sections | H14: IT | I14: Level 1 | J14: =IFERROR(INDEX(Rates!$D$6:$D$15,MATCH(H14&"|"&I14,Rates!$C$6:$C$15,0)),0) -> 100 | K14: 4 | L14: =K14*J14 -> 400 | M14: Monthly/annual toggles or more than 3 plans push this higher.
A15: 11 | C15: Homepage – Standard | D15: Galleries | E15: 14 | F15: =IFERROR(INDEX(Categories!$B$5:$B$27,MATCH(E15,Categories!$A$5:$A$27,0)),"") -> Frontend | G15: Wix gallery | H15: IT | I15: Level 1 | J15: =IFERROR(INDEX(Rates!$D$6:$D$15,MATCH(H15&"|"&I15,Rates!$C$6:$C$15,0)),0) -> 100 | K15: 2 | L15: =K15*J15 -> 200 | M15: Per gallery. Image prep is billed separately.
A16: 12 | C16: Homepage – Standard | D16: Video Embeds | E16: 14 | F16: =IFERROR(INDEX(Categories!$B$5:$B$27,MATCH(E16,Categories!$A$5:$A$27,0)),"") -> Frontend | G16: Video blocks | H16: IT | I16: Level 1 | J16: =IFERROR(INDEX(Rates!$D$6:$D$15,MATCH(H16&"|"&I16,Rates!$C$6:$C$15,0)),0) -> 100 | K16: 1 | L16: =K16*J16 -> 100 | M16: Self-hosted video or custom players are a different, larger scope.
A17: 13 | C17: Homepage – Standard | D17: Payments / Donations | E17: 15 | F17: =IFERROR(INDEX(Categories!$B$5:$B$27,MATCH(E17,Categories!$A$5:$A$27,0)),"") -> Integration | G17: Wix Payments / Stripe / PayPal | H17: IT | I17: Level 1 | J17: =IFERROR(INDEX(Rates!$D$6:$D$15,MATCH(H17&"|"&I17,Rates!$C$6:$C$15,0)),0) -> 100 | K17: 4 | L17: =K17*J17 -> 400 | M17: Excludes merchant account approval. Client delays here are common.
A18: 14 | C18: Homepage – Standard | D18: Use Cases | E18: 14 | F18: =IFERROR(INDEX(Categories!$B$5:$B$27,MATCH(E18,Categories!$A$5:$A$27,0)),"") -> Frontend | G18: Content sections | H18: IT | I18: Level 1 | J18: =IFERROR(INDEX(Rates!$D$6:$D$15,MATCH(H18&"|"&I18,Rates!$C$6:$C$15,0)),0) -> 100 | K18: 2 | L18: =K18*J18 -> 200
A19: 15 | C19: Homepage – Standard | D19: Map / Location Section | E19: 15 | F19: =IFERROR(INDEX(Categories!$B$5:$B$27,MATCH(E19,Categories!$A$5:$A$27,0)),"") -> Integration | G19: Wix map embed | H19: IT | I19: Level 1 | J19: =IFERROR(INDEX(Rates!$D$6:$D$15,MATCH(H19&"|"&I19,Rates!$C$6:$C$15,0)),0) -> 100 | K19: 2 | L19: =K19*J19 -> 200
A20: 16 | C20: Homepage – Creative | D20: Full-Screen Visuals | E20: 14 | F20: =IFERROR(INDEX(Categories!$B$5:$B$27,MATCH(E20,Categories!$A$5:$A$27,0)),"") -> Frontend | G20: Image-heavy sections | H20: Creative | I20: Level 1 | J20: =IFERROR(INDEX(Rates!$D$6:$D$15,MATCH(H20&"|"&I20,Rates!$C$6:$C$15,0)),0) -> 100 | K20: 5 | L20: =K20*J20 -> 500 | M20: Image sourcing, licensing, and retouching may be billed separately.
A21: 17 | C21: Homepage – Creative | D21: Parallax Effects | E21: 14 | F21: =IFERROR(INDEX(Categories!$B$5:$B$27,MATCH(E21,Categories!$A$5:$A$27,0)),"") -> Frontend | G21: Built-in scroll effects | H21: IT | I21: Level 2 | J21: =IFERROR(INDEX(Rates!$D$6:$D$15,MATCH(H21&"|"&I21,Rates!$C$6:$C$15,0)),0) -> 120 | K21: 3 | L21: =K21*J21 -> 360 | M21: Built-in scroll effects only. Limited compared to WordPress.
